Workbook
Name lstAnswers: SETTINGS!$G$2:$G$5
Name lstCount: SETTINGS!$E$2:$E$5
Name lstDifficulty: SETTINGS!$C$2:$C$5
Name lstGenCount: SETTINGS!$K$2:$K$6
Name lstGenDifficulty: SETTINGS!$I$2:$I$5
Name lstGenStyle: SETTINGS!$O$2:$O$5
Name lstGenType: SETTINGS!$M$2:$M$3
Name lstSubjects: SETTINGS!$A$2:$A$11

Sheet HOME
A1: EXCEL AI STUDY ASSISTANT Learn • Practice • Test • Analyze • Improve
A5: A local study desk for Excel 2021. Choose a subject and difficulty, draw a quiz from the question bank, answer in the blue cells, then review the score, explanations, and weak subtopics. History is saved by pasting the green result row into PROGRESS.
A9: START QUIZ | E9: QUIZ RESULTS | I9: STUDY PROGRESS
A10: 1. Choose a topic. 2. Choose difficulty. 3. Choose number of questions. 4. Answer the questions. 5. Check your score. | E10: Last Score | F10: =IF(QUIZ!O6=0,"-",QUIZ!O11) -> 0 / 10 | I10: Total Quizzes | J10: =PROGRESS!B5 -> 6
E11: Accuracy | F11: =IF(QUIZ!O6=0,"-",QUIZ!O12) -> 0 | I11: Average Accuracy | J11: =PROGRESS!F5 -> 0.71666667
E12: Correct Answers | F12: =QUIZ!O8 -> 0 | I12: Best Score | J12: =PROGRESS!H5 -> 1
E13: Weakest Area | F13: =RESULTS!B30 -> Integration | I13: Total Questions Attempted | J13: =PROGRESS!D5 -> 50
A16: HOW TO USE
A17: QUESTION BANK → QUIZ → RESULTS → PROGRESS 1. Add or edit questions on QUESTION_BANK. Only Active = Yes is used. Correct Answer must be A, B, C, or D. 2. On QUIZ, pick Subject, Difficulty, and Questions. Change Shuffle to draw a new set, then clear old answers. 3. Answer in the blue Your Answer cells. Result, score, and accuracy update immediately. 4. Open RESULTS to read explanations, the performance message, and the weakest subtopic. 5. Copy the green history row on RESULTS and Paste Values into the next blank row of tblHistory on PROGRESS. 6. SETTINGS holds the dropdown lists. Open QUESTION BANK or SETTINGS from the links below.
A25: QUESTION BANK | C25: SETTINGS | E25: QUIZ | G25: RESULTS | I25: PROGRESS | K25: AI GENERATOR
A27: WEAK TOPICS

Sheet QUIZ
A1: QUIZ CENTER | AA1: =COUNTIF(QUESTION_BANK!N2:N510,1) -> 14
A2: Select your settings and test your knowledge. | AA2: =IF(OR(NOT(ISNUMBER(K5)),K5<1),0,K5) -> 10
A3: ← HOME | AA3: =MIN(AA1,AA2) -> 10
A5: Subject | B5: Mathematics | F5: Difficulty | G5: Medium | J5: Questions | K5: 10 | N5: CURRENT QUIZ
A6: Shuffle | B6: 1 | C6: Type a new whole number to draw a different quiz. Clear the Your Answer cells before you reshuffle. Questions stay fixed until Shuffle changes. | N6: Total Questions | O6: =AA3 -> 10
A7: =IF(AA1=0,"No matching questions found. Please change your quiz settings or add questions to QUESTION_BANK.",IF(AA1<AA2,"Not enough questions available for this selection. Please choose another topic, difficulty, or question count. Showing "&AA3&" of "&AA2&" requested.","Ready — "&AA3&" questions drawn from "&B5&" / "&G5&". Change Shuffle to draw a new set.")) -> Ready — 10 questions drawn from Mathematics / Medium. Change Shuffle to draw a new set. | N7: Answered | O7: {=SUMPRODUCT(($AA$9:$AA$28<>"")*(I9:I28<>""))} -> 0
A8: Q# | B8: Question | I8: Your Answer | J8: Correct | K8: Result | L8: Explanation | N8: Correct | O8: =COUNTIF(K9:K28,"CORRECT") -> 0
A9: =IF(AA9="","",1) -> 1 | B9: =IF(AA9="","",_xlfn.XLOOKUP(AA9,tblQuestions[Question ID],tblQuestions[Question])&CHAR(10)&"A. "&_xlfn.XLOOKUP(AA9,tblQuestions[Question ID],tblQuestions[Option A])&CHAR(10)&"B. "&_xlfn.XLOOKUP(AA9,tblQuestions[Question ID],tblQuestions[Option B])&CHAR(10)&"C. "&_xlfn.XLOOKUP(AA9,tblQuestions[Question ID],tblQuestions[Option C])&CHAR(10)&"D. "&_xlfn.XLOOKUP(AA9,tblQuestions[Question ID],tblQuestions[Option D])) -> Using substitution, evaluate the indefinite integral of 2x(x^2+1)^3. A. (x^2+1)^4 / 4 + C B. (x^2+1)^3 / 3 + C C. 2(x^2+1)^4 + C D. x^2(x^2+1)^4 + C | J9: =IF(OR(AA9="",I9=""),"",_xlfn.XLOOKUP(AA9,tblQuestions[Question ID],tblQuestions[Correct Answer])) | K9: =IF(AA9="","",IF(I9="","NOT ANSWERED",IF(UPPER(TRIM(I9))=_xlfn.XLOOKUP(AA9,tblQuestions[Question ID],tblQuestions[Correct Answer]),"CORRECT","INCORRECT"))) -> NOT ANSWERED | L9: =IF(OR(AA9="",I9=""),"",_xlfn.XLOOKUP(AA9,tblQuestions[Question ID],tblQuestions[Explanation])) | N9: Incorrect | O9: =COUNTIF(K9:K28,"INCORRECT") -> 0 | AA9: =IF(OR($AA$3<1,1>$AA$3),"",IFERROR(INDEX(QUESTION_BANK!$A$2:$A$510,MATCH(1,QUESTION_BANK!$P$2:$P$510,0)),"")) -> MATH001
A10: =IF(AA10="","",2) -> 2 | B10: =IF(AA10="","",_xlfn.XLOOKUP(AA10,tblQuestions[Question ID],tblQuestions[Question])&CHAR(10)&"A. "&_xlfn.XLOOKUP(AA10,tblQuestions[Question ID],tblQuestions[Option A])&CHAR(10)&"B. "&_xlfn.XLOOKUP(AA10,tblQuestions[Question ID],tblQuestions[Option B])&CHAR(10)&"C. "&_xlfn.XLOOKUP(AA10,tblQuestions[Question ID],tblQuestions[Option C])&CHAR(10)&"D. "&_xlfn.XLOOKUP(AA10,tblQuestions[Question ID],tblQuestions[Option D])) -> What is the derivative of sin(x)? A. -cos(x) B. sin(x) C. cos(x) D. tan(x) | J10: =IF(OR(AA10="",I10=""),"",_xlfn.XLOOKUP(AA10,tblQuestions[Question ID],tblQuestions[Correct Answer])) | K10: =IF(AA10="","",IF(I10="","NOT ANSWERED",IF(UPPER(TRIM(I10))=_xlfn.XLOOKUP(AA10,tblQuestions[Question ID],tblQuestions[Correct Answer]),"CORRECT","INCORRECT"))) -> NOT ANSWERED | L10: =IF(OR(AA10="",I10=""),"",_xlfn.XLOOKUP(AA10,tblQuestions[Question ID],tblQuestions[Explanation])) | N10: Not Answered | O10: =COUNTIF(K9:K28,"NOT ANSWERED") -> 10 | AA10: =IF(OR($AA$3<1,2>$AA$3),"",IFERROR(INDEX(QUESTION_BANK!$A$2:$A$510,MATCH(2,QUESTION_BANK!$P$2:$P$510,0)),"")) -> Q002
A11: =IF(AA11="","",3) -> 3 | B11: =IF(AA11="","",_xlfn.XLOOKUP(AA11,tblQuestions[Question ID],tblQuestions[Question])&CHAR(10)&"A. "&_xlfn.XLOOKUP(AA11,tblQuestions[Question ID],tblQuestions[Option A])&CHAR(10)&"B. "&_xlfn.XLOOKUP(AA11,tblQuestions[Question ID],tblQuestions[Option B])&CHAR(10)&"C. "&_xlfn.XLOOKUP(AA11,tblQuestions[Question ID],tblQuestions[Option C])&CHAR(10)&"D. "&_xlfn.XLOOKUP(AA11,tblQuestions[Question ID],tblQuestions[Option D])) -> Using substitution, evaluate the indefinite integral of 2x e^(x^2). A. e^(x^2) + C B. 2e^(x^2) + C C. x e^(x^2) + C D. e^(2x) + C | J11: =IF(OR(AA11="",I11=""),"",_xlfn.XLOOKUP(AA11,tblQuestions[Question ID],tblQuestions[Correct Answer])) | K11: =IF(AA11="","",IF(I11="","NOT ANSWERED",IF(UPPER(TRIM(I11))=_xlfn.XLOOKUP(AA11,tblQuestions[Question ID],tblQuestions[Correct Answer]),"CORRECT","INCORRECT"))) -> NOT ANSWERED | L11: =IF(OR(AA11="",I11=""),"",_xlfn.XLOOKUP(AA11,tblQuestions[Question ID],tblQuestions[Explanation])) | N11: Score | O11: =IF(O6=0,"—",O8&" / "&O6) -> 0 / 10 | AA11: =IF(OR($AA$3<1,3>$AA$3),"",IFERROR(INDEX(QUESTION_BANK!$A$2:$A$510,MATCH(3,QUESTION_BANK!$P$2:$P$510,0)),"")) -> MATH002
A12: =IF(AA12="","",4) -> 4 | B12: =IF(AA12="","",_xlfn.XLOOKUP(AA12,tblQuestions[Question ID],tblQuestions[Question])&CHAR(10)&"A. "&_xlfn.XLOOKUP(AA12,tblQuestions[Question ID],tblQuestions[Option A])&CHAR(10)&"B. "&_xlfn.XLOOKUP(AA12,tblQuestions[Question ID],tblQuestions[Option B])&CHAR(10)&"C. "&_xlfn.XLOOKUP(AA12,tblQuestions[Question ID],tblQuestions[Option C])&CHAR(10)&"D. "&_xlfn.XLOOKUP(AA12,tblQuestions[Question ID],tblQuestions[Option D])) -> Evaluate the definite integral of 2x from 0 to 1. A. 1 B. 2 C. 0 D. 1/2 | J12: =IF(OR(AA12="",I12=""),"",_xlfn.XLOOKUP(AA12,tblQuestions[Question ID],tblQuestions[Correct Answer])) | K12: =IF(AA12="","",IF(I12="","NOT ANSWERED",IF(UPPER(TRIM(I12))=_xlfn.XLOOKUP(AA12,tblQuestions[Question ID],tblQuestions[Correct Answer]),"CORRECT","INCORRECT"))) -> NOT ANSWERED | L12: =IF(OR(AA12="",I12=""),"",_xlfn.XLOOKUP(AA12,tblQuestions[Question ID],tblQuestions[Explanation])) | N12: Accuracy | O12: =IF(O6=0,"—",O8/O6) -> 0 | AA12: =IF(OR($AA$3<1,4>$AA$3),"",IFERROR(INDEX(QUESTION_BANK!$A$2:$A$510,MATCH(4,QUESTION_BANK!$P$2:$P$510,0)),"")) -> MATH003
A13: =IF(AA13="","",5) -> 5 | B13: =IF(AA13="","",_xlfn.XLOOKUP(AA13,tblQuestions[Question ID],tblQuestions[Question])&CHAR(10)&"A. "&_xlfn.XLOOKUP(AA13,tblQuestions[Question ID],tblQuestions[Option A])&CHAR(10)&"B. "&_xlfn.XLOOKUP(AA13,tblQuestions[Question ID],tblQuestions[Option B])&CHAR(10)&"C. "&_xlfn.XLOOKUP(AA13,tblQuestions[Question ID],tblQuestions[Option C])&CHAR(10)&"D. "&_xlfn.XLOOKUP(AA13,tblQuestions[Question ID],tblQuestions[Option D])) -> What is the indefinite integral of 1/x? A. x + C B. 1/x² + C C. ln|x| + C D. e^x + C | J13: =IF(OR(AA13="",I13=""),"",_xlfn.XLOOKUP(AA13,tblQuestions[Question ID],tblQuestions[Correct Answer])) | K13: =IF(AA13="","",IF(I13="","NOT ANSWERED",IF(UPPER(TRIM(I13))=_xlfn.XLOOKUP(AA13,tblQuestions[Question ID],tblQuestions[Correct Answer]),"CORRECT","INCORRECT"))) -> NOT ANSWERED | L13: =IF(OR(AA13="",I13=""),"",_xlfn.XLOOKUP(AA13,tblQuestions[Question ID],tblQuestions[Explanation])) | AA13: =IF(OR($AA$3<1,5>$AA$3),"",IFERROR(INDEX(QUESTION_BANK!$A$2:$A$510,MATCH(5,QUESTION_BANK!$P$2:$P$510,0)),"")) -> Q004
A14: =IF(AA14="","",6) -> 6 | B14: =IF(AA14="","",_xlfn.XLOOKUP(AA14,tblQuestions[Question ID],tblQuestions[Question])&CHAR(10)&"A. "&_xlfn.XLOOKUP(AA14,tblQuestions[Question ID],tblQuestions[Option A])&CHAR(10)&"B. "&_xlfn.XLOOKUP(AA14,tblQuestions[Question ID],tblQuestions[Option B])&CHAR(10)&"C. "&_xlfn.XLOOKUP(AA14,tblQuestions[Question ID],tblQuestions[Option C])&CHAR(10)&"D. "&_xlfn.XLOOKUP(AA14,tblQuestions[Question ID],tblQuestions[Option D])) -> Evaluate the definite integral of 3x^2 from 0 to 2. A. 8 B. 12 C. 4 D. 6 | J14: =IF(OR(AA14="",I14=""),"",_xlfn.XLOOKUP(AA14,tblQuestions[Question ID],tblQuestions[Correct Answer])) | K14: =IF(AA14="","",IF(I14="","NOT ANSWERED",IF(UPPER(TRIM(I14))=_xlfn.XLOOKUP(AA14,tblQuestions[Question ID],tblQuestions[Correct Answer]),"CORRECT","INCORRECT"))) -> NOT ANSWERED | L14: =IF(OR(AA14="",I14=""),"",_xlfn.XLOOKUP(AA14,tblQuestions[Question ID],tblQuestions[Explanation])) | N14: → RESULTS | AA14: =IF(OR($AA$3<1,6>$AA$3),"",IFERROR(INDEX(QUESTION_BANK!$A$2:$A$510,MATCH(6,QUESTION_BANK!$P$2:$P$510,0)),"")) -> MATH004
A15: =IF(AA15="","",7) -> 7 | B15: =IF(AA15="","",_xlfn.XLOOKUP(AA15,tblQuestions[Question ID],tblQuestions[Question])&CHAR(10)&"A. "&_xlfn.XLOOKUP(AA15,tblQuestions[Question ID],tblQuestions[Option A])&CHAR(10)&"B. "&_xlfn.XLOOKUP(AA15,tblQuestions[Question ID],tblQuestions[Option B])&CHAR(10)&"C. "&_xlfn.XLOOKUP(AA15,tblQuestions[Question ID],tblQuestions[Option C])&CHAR(10)&"D. "&_xlfn.XLOOKUP(AA15,tblQuestions[Question ID],tblQuestions[Option D])) -> Using substitution, evaluate the indefinite integral of 2x/(x^2+1). A. ln|x^2+1| + C B. 2 ln|x^2+1| + C C. ln|2x| + C D. arctan(x^2) + C | J15: =IF(OR(AA15="",I15=""),"",_xlfn.XLOOKUP(AA15,tblQuestions[Question ID],tblQuestions[Correct Answer])) | K15: =IF(AA15="","",IF(I15="","NOT ANSWERED",IF(UPPER(TRIM(I15))=_xlfn.XLOOKUP(AA15,tblQuestions[Question ID],tblQuestions[Correct Answer]),"CORRECT","INCORRECT"))) -> NOT ANSWERED | L15: =IF(OR(AA15="",I15=""),"",_xlfn.XLOOKUP(AA15,tblQuestions[Question ID],tblQuestions[Explanation])) | AA15: =IF(OR($AA$3<1,7>$AA$3),"",IFERROR(INDEX(QUESTION_BANK!$A$2:$A$510,MATCH(7,QUESTION_BANK!$P$2:$P$510,0)),"")) -> MATH005
A16: =IF(AA16="","",8) -> 8 | B16: =IF(AA16="","",_xlfn.XLOOKUP(AA16,tblQuestions[Question ID],tblQuestions[Question])&CHAR(10)&"A. "&_xlfn.XLOOKUP(AA16,tblQuestions[Question ID],tblQuestions[Option A])&CHAR(10)&"B. "&_xlfn.XLOOKUP(AA16,tblQuestions[Question ID],tblQuestions[Option B])&CHAR(10)&"C. "&_xlfn.XLOOKUP(AA16,tblQuestions[Question ID],tblQuestions[Option C])&CHAR(10)&"D. "&_xlfn.XLOOKUP(AA16,tblQuestions[Question ID],tblQuestions[Option D])) -> What are the roots of x² − 5x + 6 = 0? A. 1 and 6 B. 2 and 3 C. −2 and −3 D. 5 and 6 | J16: =IF(OR(AA16="",I16=""),"",_xlfn.XLOOKUP(AA16,tblQuestions[Question ID],tblQuestions[Correct Answer])) | K16: =IF(AA16="","",IF(I16="","NOT ANSWERED",IF(UPPER(TRIM(I16))=_xlfn.XLOOKUP(AA16,tblQuestions[Question ID],tblQuestions[Correct Answer]),"CORRECT","INCORRECT"))) -> NOT ANSWERED | L16: =IF(OR(AA16="",I16=""),"",_xlfn.XLOOKUP(AA16,tblQuestions[Question ID],tblQuestions[Explanation])) | AA16: =IF(OR($AA$3<1,8>$AA$3),"",IFERROR(INDEX(QUESTION_BANK!$A$2:$A$510,MATCH(8,QUESTION_BANK!$P$2:$P$510,0)),"")) -> Q006
A17: =IF(AA17="","",9) -> 9 | B17: =IF(AA17="","",_xlfn.XLOOKUP(AA17,tblQuestions[Question ID],tblQuestions[Question])&CHAR(10)&"A. "&_xlfn.XLOOKUP(AA17,tblQuestions[Question ID],tblQuestions[Option A])&CHAR(10)&"B. "&_xlfn.XLOOKUP(AA17,tblQuestions[Question ID],tblQuestions[Option B])&CHAR(10)&"C. "&_xlfn.XLOOKUP(AA17,tblQuestions[Question ID],tblQuestions[Option C])&CHAR(10)&"D. "&_xlfn.XLOOKUP(AA17,tblQuestions[Question ID],tblQuestions[Option D])) -> Evaluate the definite integral of 1/x from 1 to e. A. 1 B. e C. 0 D. e-1 | J17: =IF(OR(AA17="",I17=""),"",_xlfn.XLOOKUP(AA17,tblQuestions[Question ID],tblQuestions[Correct Answer])) | K17: =IF(AA17="","",IF(I17="","NOT ANSWERED",IF(UPPER(TRIM(I17))=_xlfn.XLOOKUP(AA17,tblQuestions[Question ID],tblQuestions[Correct Answer]),"CORRECT","INCORRECT"))) -> NOT ANSWERED | L17: =IF(OR(AA17="",I17=""),"",_xlfn.XLOOKUP(AA17,tblQuestions[Question ID],tblQuestions[Explanation])) | AA17: =IF(OR($AA$3<1,9>$AA$3),"",IFERROR(INDEX(QUESTION_BANK!$A$2:$A$510,MATCH(9,QUESTION_BANK!$P$2:$P$510,0)),"")) -> MATH006
A18: =IF(AA18="","",10) -> 10 | B18: =IF(AA18="","",_xlfn.XLOOKUP(AA18,tblQuestions[Question ID],tblQuestions[Question])&CHAR(10)&"A. "&_xlfn.XLOOKUP(AA18,tblQuestions[Question ID],tblQuestions[Option A])&CHAR(10)&"B. "&_xlfn.XLOOKUP(AA18,tblQuestions[Question ID],tblQuestions[Option B])&CHAR(10)&"C. "&_xlfn.XLOOKUP(AA18,tblQuestions[Question ID],tblQuestions[Option C])&CHAR(10)&"D. "&_xlfn.XLOOKUP(AA18,tblQuestions[Question ID],tblQuestions[Option D])) -> Using the substitution u = sin(x), evaluate the indefinite integral of sin(x)cos(x). A. (1/2) sin^2(x) + C B. sin^2(x) + C C. cos^2(x) + C D. negative cos(x) + C | J18: =IF(OR(AA18="",I18=""),"",_xlfn.XLOOKUP(AA18,tblQuestions[Question ID],tblQuestions[Correct Answer])) | K18: =IF(AA18="","",IF(I18="","NOT ANSWERED",IF(UPPER(TRIM(I18))=_xlfn.XLOOKUP(AA18,tblQuestions[Question ID],tblQuestions[Correct Answer]),"CORRECT","INCORRECT"))) -> NOT ANSWERED | L18: =IF(OR(AA18="",I18=""),"",_xlfn.XLOOKUP(AA18,tblQuestions[Question ID],tblQuestions[Explanation])) | AA18: =IF(OR($AA$3<1,10>$AA$3),"",IFERROR(INDEX(QUESTION_BANK!$A$2:$A$510,MATCH(10,QUESTION_BANK!$P$2:$P$510,0)),"")) -> MATH007
A19: =IF(AA19="","",11) | B19: =IF(AA19="","",_xlfn.XLOOKUP(AA19,tblQuestions[Question ID],tblQuestions[Question])&CHAR(10)&"A. "&_xlfn.XLOOKUP(AA19,tblQuestions[Question ID],tblQuestions[Option A])&CHAR(10)&"B. "&_xlfn.XLOOKUP(AA19,tblQuestions[Question ID],tblQuestions[Option B])&CHAR(10)&"C. "&_xlfn.XLOOKUP(AA19,tblQuestions[Question ID],tblQuestions[Option C])&CHAR(10)&"D. "&_xlfn.XLOOKUP(AA19,tblQuestions[Question ID],tblQuestions[Option D])) | J19: =IF(OR(AA19="",I19=""),"",_xlfn.XLOOKUP(AA19,tblQuestions[Question ID],tblQuestions[Correct Answer])) | K19: =IF(AA19="","",IF(I19="","NOT ANSWERED",IF(UPPER(TRIM(I19))=_xlfn.XLOOKUP(AA19,tblQuestions[Question ID],tblQuestions[Correct Answer]),"CORRECT","INCORRECT"))) | L19: =IF(OR(AA19="",I19=""),"",_xlfn.XLOOKUP(AA19,tblQuestions[Question ID],tblQuestions[Explanation])) | AA19: =IF(OR($AA$3<1,11>$AA$3),"",IFERROR(INDEX(QUESTION_BANK!$A$2:$A$510,MATCH(11,QUESTION_BANK!$P$2:$P$510,0)),""))
A20: =IF(AA20="","",12) | B20: =IF(AA20="","",_xlfn.XLOOKUP(AA20,tblQuestions[Question ID],tblQuestions[Question])&CHAR(10)&"A. "&_xlfn.XLOOKUP(AA20,tblQuestions[Question ID],tblQuestions[Option A])&CHAR(10)&"B. "&_xlfn.XLOOKUP(AA20,tblQuestions[Question ID],tblQuestions[Option B])&CHAR(10)&"C. "&_xlfn.XLOOKUP(AA20,tblQuestions[Question ID],tblQuestions[Option C])&CHAR(10)&"D. "&_xlfn.XLOOKUP(AA20,tblQuestions[Question ID],tblQuestions[Option D])) | J20: =IF(OR(AA20="",I20=""),"",_xlfn.XLOOKUP(AA20,tblQuestions[Question ID],tblQuestions[Correct Answer])) | K20: =IF(AA20="","",IF(I20="","NOT ANSWERED",IF(UPPER(TRIM(I20))=_xlfn.XLOOKUP(AA20,tblQuestions[Question ID],tblQuestions[Correct Answer]),"CORRECT","INCORRECT"))) | L20: =IF(OR(AA20="",I20=""),"",_xlfn.XLOOKUP(AA20,tblQuestions[Question ID],tblQuestions[Explanation])) | AA20: =IF(OR($AA$3<1,12>$AA$3),"",IFERROR(INDEX(QUESTION_BANK!$A$2:$A$510,MATCH(12,QUESTION_BANK!$P$2:$P$510,0)),""))
A21: =IF(AA21="","",13) | B21: =IF(AA21="","",_xlfn.XLOOKUP(AA21,tblQuestions[Question ID],tblQuestions[Question])&CHAR(10)&"A. "&_xlfn.XLOOKUP(AA21,tblQuestions[Question ID],tblQuestions[Option A])&CHAR(10)&"B. "&_xlfn.XLOOKUP(AA21,tblQuestions[Question ID],tblQuestions[Option B])&CHAR(10)&"C. "&_xlfn.XLOOKUP(AA21,tblQuestions[Question ID],tblQuestions[Option C])&CHAR(10)&"D. "&_xlfn.XLOOKUP(AA21,tblQuestions[Question ID],tblQuestions[Option D])) | J21: =IF(OR(AA21="",I21=""),"",_xlfn.XLOOKUP(AA21,tblQuestions[Question ID],tblQuestions[Correct Answer])) | K21: =IF(AA21="","",IF(I21="","NOT ANSWERED",IF(UPPER(TRIM(I21))=_xlfn.XLOOKUP(AA21,tblQuestions[Question ID],tblQuestions[Correct Answer]),"CORRECT","INCORRECT"))) | L21: =IF(OR(AA21="",I21=""),"",_xlfn.XLOOKUP(AA21,tblQuestions[Question ID],tblQuestions[Explanation])) | AA21: =IF(OR($AA$3<1,13>$AA$3),"",IFERROR(INDEX(QUESTION_BANK!$A$2:$A$510,MATCH(13,QUESTION_BANK!$P$2:$P$510,0)),""))
A22: =IF(AA22="","",14) | B22: =IF(AA22="","",_xlfn.XLOOKUP(AA22,tblQuestions[Question ID],tblQuestions[Question])&CHAR(10)&"A. "&_xlfn.XLOOKUP(AA22,tblQuestions[Question ID],tblQuestions[Option A])&CHAR(10)&"B. "&_xlfn.XLOOKUP(AA22,tblQuestions[Question ID],tblQuestions[Option B])&CHAR(10)&"C. "&_xlfn.XLOOKUP(AA22,tblQuestions[Question ID],tblQuestions[Option C])&CHAR(10)&"D. "&_xlfn.XLOOKUP(AA22,tblQuestions[Question ID],tblQuestions[Option D])) | J22: =IF(OR(AA22="",I22=""),"",_xlfn.XLOOKUP(AA22,tblQuestions[Question ID],tblQuestions[Correct Answer])) | K22: =IF(AA22="","",IF(I22="","NOT ANSWERED",IF(UPPER(TRIM(I22))=_xlfn.XLOOKUP(AA22,tblQuestions[Question ID],tblQuestions[Correct Answer]),"CORRECT","INCORRECT"))) | L22: =IF(OR(AA22="",I22=""),"",_xlfn.XLOOKUP(AA22,tblQuestions[Question ID],tblQuestions[Explanation])) | AA22: =IF(OR($AA$3<1,14>$AA$3),"",IFERROR(INDEX(QUESTION_BANK!$A$2:$A$510,MATCH(14,QUESTION_BANK!$P$2:$P$510,0)),""))
A23: =IF(AA23="","",15) | B23: =IF(AA23="","",_xlfn.XLOOKUP(AA23,tblQuestions[Question ID],tblQuestions[Question])&CHAR(10)&"A. "&_xlfn.XLOOKUP(AA23,tblQuestions[Question ID],tblQuestions[Option A])&CHAR(10)&"B. "&_xlfn.XLOOKUP(AA23,tblQuestions[Question ID],tblQuestions[Option B])&CHAR(10)&"C. "&_xlfn.XLOOKUP(AA23,tblQuestions[Question ID],tblQuestions[Option C])&CHAR(10)&"D. "&_xlfn.XLOOKUP(AA23,tblQuestions[Question ID],tblQuestions[Option D])) | J23: =IF(OR(AA23="",I23=""),"",_xlfn.XLOOKUP(AA23,tblQuestions[Question ID],tblQuestions[Correct Answer])) | K23: =IF(AA23="","",IF(I23="","NOT ANSWERED",IF(UPPER(TRIM(I23))=_xlfn.XLOOKUP(AA23,tblQuestions[Question ID],tblQuestions[Correct Answer]),"CORRECT","INCORRECT"))) | L23: =IF(OR(AA23="",I23=""),"",_xlfn.XLOOKUP(AA23,tblQuestions[Question ID],tblQuestions[Explanation])) | AA23: =IF(OR($AA$3<1,15>$AA$3),"",IFERROR(INDEX(QUESTION_BANK!$A$2:$A$510,MATCH(15,QUESTION_BANK!$P$2:$P$510,0)),""))
A24: =IF(AA24="","",16) | B24: =IF(AA24="","",_xlfn.XLOOKUP(AA24,tblQuestions[Question ID],tblQuestions[Question])&CHAR(10)&"A. "&_xlfn.XLOOKUP(AA24,tblQuestions[Question ID],tblQuestions[Option A])&CHAR(10)&"B. "&_xlfn.XLOOKUP(AA24,tblQuestions[Question ID],tblQuestions[Option B])&CHAR(10)&"C. "&_xlfn.XLOOKUP(AA24,tblQuestions[Question ID],tblQuestions[Option C])&CHAR(10)&"D. "&_xlfn.XLOOKUP(AA24,tblQuestions[Question ID],tblQuestions[Option D])) | J24: =IF(OR(AA24="",I24=""),"",_xlfn.XLOOKUP(AA24,tblQuestions[Question ID],tblQuestions[Correct Answer])) | K24: =IF(AA24="","",IF(I24="","NOT ANSWERED",IF(UPPER(TRIM(I24))=_xlfn.XLOOKUP(AA24,tblQuestions[Question ID],tblQuestions[Correct Answer]),"CORRECT","INCORRECT"))) | L24: =IF(OR(AA24="",I24=""),"",_xlfn.XLOOKUP(AA24,tblQuestions[Question ID],tblQuestions[Explanation])) | AA24: =IF(OR($AA$3<1,16>$AA$3),"",IFERROR(INDEX(QUESTION_BANK!$A$2:$A$510,MATCH(16,QUESTION_BANK!$P$2:$P$510,0)),""))
A25: =IF(AA25="","",17) | B25: =IF(AA25="","",_xlfn.XLOOKUP(AA25,tblQuestions[Question ID],tblQuestions[Question])&CHAR(10)&"A. "&_xlfn.XLOOKUP(AA25,tblQuestions[Question ID],tblQuestions[Option A])&CHAR(10)&"B. "&_xlfn.XLOOKUP(AA25,tblQuestions[Question ID],tblQuestions[Option B])&CHAR(10)&"C. "&_xlfn.XLOOKUP(AA25,tblQuestions[Question ID],tblQuestions[Option C])&CHAR(10)&"D. "&_xlfn.XLOOKUP(AA25,tblQuestions[Question ID],tblQuestions[Option D])) | J25: =IF(OR(AA25="",I25=""),"",_xlfn.XLOOKUP(AA25,tblQuestions[Question ID],tblQuestions[Correct Answer])) | K25: =IF(AA25="","",IF(I25="","NOT ANSWERED",IF(UPPER(TRIM(I25))=_xlfn.XLOOKUP(AA25,tblQuestions[Question ID],tblQuestions[Correct Answer]),"CORRECT","INCORRECT"))) | L25: =IF(OR(AA25="",I25=""),"",_xlfn.XLOOKUP(AA25,tblQuestions[Question ID],tblQuestions[Explanation])) | AA25: =IF(OR($AA$3<1,17>$AA$3),"",IFERROR(INDEX(QUESTION_BANK!$A$2:$A$510,MATCH(17,QUESTION_BANK!$P$2:$P$510,0)),""))
A26: =IF(AA26="","",18) | B26: =IF(AA26="","",_xlfn.XLOOKUP(AA26,tblQuestions[Question ID],tblQuestions[Question])&CHAR(10)&"A. "&_xlfn.XLOOKUP(AA26,tblQuestions[Question ID],tblQuestions[Option A])&CHAR(10)&"B. "&_xlfn.XLOOKUP(AA26,tblQuestions[Question ID],tblQuestions[Option B])&CHAR(10)&"C. "&_xlfn.XLOOKUP(AA26,tblQuestions[Question ID],tblQuestions[Option C])&CHAR(10)&"D. "&_xlfn.XLOOKUP(AA26,tblQuestions[Question ID],tblQuestions[Option D])) | J26: =IF(OR(AA26="",I26=""),"",_xlfn.XLOOKUP(AA26,tblQuestions[Question ID],tblQuestions[Correct Answer])) | K26: =IF(AA26="","",IF(I26="","NOT ANSWERED",IF(UPPER(TRIM(I26))=_xlfn.XLOOKUP(AA26,tblQuestions[Question ID],tblQuestions[Correct Answer]),"CORRECT","INCORRECT"))) | L26: =IF(OR(AA26="",I26=""),"",_xlfn.XLOOKUP(AA26,tblQuestions[Question ID],tblQuestions[Explanation])) | AA26: =IF(OR($AA$3<1,18>$AA$3),"",IFERROR(INDEX(QUESTION_BANK!$A$2:$A$510,MATCH(18,QUESTION_BANK!$P$2:$P$510,0)),""))
A27: =IF(AA27="","",19) | B27: =IF(AA27="","",_xlfn.XLOOKUP(AA27,tblQuestions[Question ID],tblQuestions[Question])&CHAR(10)&"A. "&_xlfn.XLOOKUP(AA27,tblQuestions[Question ID],tblQuestions[Option A])&CHAR(10)&"B. "&_xlfn.XLOOKUP(AA27,tblQuestions[Question ID],tblQuestions[Option B])&CHAR(10)&"C. "&_xlfn.XLOOKUP(AA27,tblQuestions[Question ID],tblQuestions[Option C])&CHAR(10)&"D. "&_xlfn.XLOOKUP(AA27,tblQuestions[Question ID],tblQuestions[Option D])) | J27: =IF(OR(AA27="",I27=""),"",_xlfn.XLOOKUP(AA27,tblQuestions[Question ID],tblQuestions[Correct Answer])) | K27: =IF(AA27="","",IF(I27="","NOT ANSWERED",IF(UPPER(TRIM(I27))=_xlfn.XLOOKUP(AA27,tblQuestions[Question ID],tblQuestions[Correct Answer]),"CORRECT","INCORRECT"))) | L27: =IF(OR(AA27="",I27=""),"",_xlfn.XLOOKUP(AA27,tblQuestions[Question ID],tblQuestions[Explanation])) | AA27: =IF(OR($AA$3<1,19>$AA$3),"",IFERROR(INDEX(QUESTION_BANK!$A$2:$A$510,MATCH(19,QUESTION_BANK!$P$2:$P$510,0)),""))
A28: =IF(AA28="","",20) | B28: =IF(AA28="","",_xlfn.XLOOKUP(AA28,tblQuestions[Question ID],tblQuestions[Question])&CHAR(10)&"A. "&_xlfn.XLOOKUP(AA28,tblQuestions[Question ID],tblQuestions[Option A])&CHAR(10)&"B. "&_xlfn.XLOOKUP(AA28,tblQuestions[Question ID],tblQuestions[Option B])&CHAR(10)&"C. "&_xlfn.XLOOKUP(AA28,tblQuestions[Question ID],tblQuestions[Option C])&CHAR(10)&"D. "&_xlfn.XLOOKUP(AA28,tblQuestions[Question ID],tblQuestions[Option D])) | J28: =IF(OR(AA28="",I28=""),"",_xlfn.XLOOKUP(AA28,tblQuestions[Question ID],tblQuestions[Correct Answer])) | K28: =IF(AA28="","",IF(I28="","NOT ANSWERED",IF(UPPER(TRIM(I28))=_xlfn.XLOOKUP(AA28,tblQuestions[Question ID],tblQuestions[Correct Answer]),"CORRECT","INCORRECT"))) | L28: =IF(OR(AA28="",I28=""),"",_xlfn.XLOOKUP(AA28,tblQuestions[Question ID],tblQuestions[Explanation])) | AA28: =IF(OR($AA$3<1,20>$AA$3),"",IFERROR(INDEX(QUESTION_BANK!$A$2:$A$510,MATCH(20,QUESTION_BANK!$P$2:$P$510,0)),""))

Sheet QUESTION_BANK
A1: Question ID | B1: Subject | C1: Topic | D1: Subtopic | E1: Difficulty | F1: Question | G1: Option A | H1: Option B | I1: Option C | J1: Option D | K1: Correct Answer | L1: Explanation | M1: Active | N1: Eligible | O1: Rank Key | P1: Draw Rank | R1: AI QUESTION GENERATOR
A2: Q001 | B2: Mathematics | C2: Calculus | D2: Derivatives | E2: Easy | F2: What is the derivative of x²? | G2: x | H2: 2x | I2: x² | J2: 2 | K2: B | L2: The power rule gives d/dx(x²) = 2x. | M2: Yes | N2: =IF(AND(M2="Yes",OR(QUIZ!$B$5="All Subjects",B2=QUIZ!$B$5),OR(QUIZ!$G$5="All Difficulties",E2=QUIZ!$G$5)),1,0) -> 0 | O2: =IF(N2=0,999999,MOD(IFERROR(VALUE(RIGHT(A2,3)),ROW())*7919+IF(N(QUIZ!$B$6)=0,1,QUIZ!$B$6)*104729+ROW()*IF(N(QUIZ!$B$6)=0,1,QUIZ!$B$6),999983)+ROW()/1000) -> 999999 | P2: =IF(N2=0,"",COUNTIFS($N$2:$N$510,1,$O$2:$O$510,"<"&O2)+1)
A3: Q002 | B3: Mathematics | C3: Calculus | D3: Derivatives | E3: Medium | F3: What is the derivative of sin(x)? | G3: -cos(x) | H3: sin(x) | I3: cos(x) | J3: tan(x) | K3: C | L3: The derivative of sin(x) is cos(x). | M3: Yes | N3: =IF(AND(M3="Yes",OR(QUIZ!$B$5="All Subjects",B3=QUIZ!$B$5),OR(QUIZ!$G$5="All Difficulties",E3=QUIZ!$G$5)),1,0) -> 1 | O3: =IF(N3=0,999999,MOD(IFERROR(VALUE(RIGHT(A3,3)),ROW())*7919+IF(N(QUIZ!$B$6)=0,1,QUIZ!$B$6)*104729+ROW()*IF(N(QUIZ!$B$6)=0,1,QUIZ!$B$6),999983)+ROW()/1000) -> 120570 | P3: =IF(N3=0,"",COUNTIFS($N$2:$N$510,1,$O$2:$O$510,"<"&O3)+1) -> 2
A4: Q003 | B4: Mathematics | C4: Calculus | D4: Integration | E4: Easy | F4: What is the indefinite integral of 2x? | G4: x² + C | H4: 2x² + C | I4: x + C | J4: 2 + C | K4: A | L4: Integrating 2x with the power rule gives x² + C. | M4: Yes | N4: =IF(AND(M4="Yes",OR(QUIZ!$B$5="All Subjects",B4=QUIZ!$B$5),OR(QUIZ!$G$5="All Difficulties",E4=QUIZ!$G$5)),1,0) -> 0 | O4: =IF(N4=0,999999,MOD(IFERROR(VALUE(RIGHT(A4,3)),ROW())*7919+IF(N(QUIZ!$B$6)=0,1,QUIZ!$B$6)*104729+ROW()*IF(N(QUIZ!$B$6)=0,1,QUIZ!$B$6),999983)+ROW()/1000) -> 999999 | P4: =IF(N4=0,"",COUNTIFS($N$2:$N$510,1,$O$2:$O$510,"<"&O4)+1)
A5: Q004 | B5: Mathematics | C5: Calculus | D5: Integration | E5: Medium | F5: What is the indefinite integral of 1/x? | G5: x + C | H5: 1/x² + C | I5: ln|x| + C | J5: e^x + C | K5: C | L5: The integral of 1/x is the natural log of the absolute value of x, plus C. | M5: Yes | N5: =IF(AND(M5="Yes",OR(QUIZ!$B$5="All Subjects",B5=QUIZ!$B$5),OR(QUIZ!$G$5="All Difficulties",E5=QUIZ!$G$5)),1,0) -> 1 | O5: =IF(N5=0,999999,MOD(IFERROR(VALUE(RIGHT(A5,3)),ROW())*7919+IF(N(QUIZ!$B$6)=0,1,QUIZ!$B$6)*104729+ROW()*IF(N(QUIZ!$B$6)=0,1,QUIZ!$B$6),999983)+ROW()/1000) -> 136410.01 | P5: =IF(N5=0,"",COUNTIFS($N$2:$N$510,1,$O$2:$O$510,"<"&O5)+1) -> 5
A6: Q005 | B6: Mathematics | C6: Algebra | D6: Linear Equations | E6: Easy | F6: Solve 2x + 3 = 11. | G6: x = 3 | H6: x = 4 | I6: x = 5 | J6: x = 7 | K6: B | L6: Subtract 3 from both sides, then divide by 2: x = 4. | M6: Yes | N6: =IF(AND(M6="Yes",OR(QUIZ!$B$5="All Subjects",B6=QUIZ!$B$5),OR(QUIZ!$G$5="All Difficulties",E6=QUIZ!$G$5)),1,0) -> 0 | O6: =IF(N6=0,999999,MOD(IFERROR(VALUE(RIGHT(A6,3)),ROW())*7919+IF(N(QUIZ!$B$6)=0,1,QUIZ!$B$6)*104729+ROW()*IF(N(QUIZ!$B$6)=0,1,QUIZ!$B$6),999983)+ROW()/1000) -> 999999 | P6: =IF(N6=0,"",COUNTIFS($N$2:$N$510,1,$O$2:$O$510,"<"&O6)+1)
A7: Q006 | B7: Mathematics | C7: Algebra | D7: Quadratic Equations | E7: Medium | F7: What are the roots of x² − 5x + 6 = 0? | G7: 1 and 6 | H7: 2 and 3 | I7: −2 and −3 | J7: 5 and 6 | K7: B | L7: The quadratic factors as (x − 2)(x − 3) = 0. | M7: Yes | N7: =IF(AND(M7="Yes",OR(QUIZ!$B$5="All Subjects",B7=QUIZ!$B$5),OR(QUIZ!$G$5="All Difficulties",E7=QUIZ!$G$5)),1,0) -> 1 | O7: =IF(N7=0,999999,MOD(IFERROR(VALUE(RIGHT(A7,3)),ROW())*7919+IF(N(QUIZ!$B$6)=0,1,QUIZ!$B$6)*104729+ROW()*IF(N(QUIZ!$B$6)=0,1,QUIZ!$B$6),999983)+ROW()/1000) -> 152250.01 | P7: =IF(N7=0,"",COUNTIFS($N$2:$N$510,1,$O$2:$O$510,"<"&O7)+1) -> 8
A8: Q007 | B8: Mathematics | C8: Statistics | D8: Descriptive | E8: Easy | F8: What is the mean of 2, 4, 6, and 8? | G8: 4 | H8: 5 | I8: 6 | J8: 8 | K8: B | L8: The mean is (2 + 4 + 6 + 8) / 4 = 5. | M8: Yes | N8: =IF(AND(M8="Yes",OR(QUIZ!$B$5="All Subjects",B8=QUIZ!$B$5),OR(QUIZ!$G$5="All Difficulties",E8=QUIZ!$G$5)),1,0) -> 0 | O8: =IF(N8=0,999999,MOD(IFERROR(VALUE(RIGHT(A8,3)),ROW())*7919+IF(N(QUIZ!$B$6)=0,1,QUIZ!$B$6)*104729+ROW()*IF(N(QUIZ!$B$6)=0,1,QUIZ!$B$6),999983)+ROW()/1000) -> 999999 | P8: =IF(N8=0,"",COUNTIFS($N$2:$N$510,1,$O$2:$O$510,"<"&O8)+1)
A9: Q008 | B9: Mathematics | C9: Statistics | D9: Probability | E9: Medium | F9: A fair coin is flipped twice. What is the probability of two heads? | G9: 1/2 | H9: 1/3 | I9: 1/4 | J9: 1/8 | K9: C | L9: The flips are independent, so (1/2) × (1/2) = 1/4. | M9: Yes | N9: =IF(AND(M9="Yes",OR(QUIZ!$B$5="All Subjects",B9=QUIZ!$B$5),OR(QUIZ!$G$5="All Difficulties",E9=QUIZ!$G$5)),1,0) -> 1 | O9: =IF(N9=0,999999,MOD(IFERROR(VALUE(RIGHT(A9,3)),ROW())*7919+IF(N(QUIZ!$B$6)=0,1,QUIZ!$B$6)*104729+ROW()*IF(N(QUIZ!$B$6)=0,1,QUIZ!$B$6),999983)+ROW()/1000) -> 168090.01 | P9: =IF(N9=0,"",COUNTIFS($N$2:$N$510,1,$O$2:$O$510,"<"&O9)+1) -> 11
A10: Q009 | B10: Accounting | C10: Journal Entries | D10: Debits and Credits | E10: Easy | F10: Which account normally increases with a debit? | G10: Revenue | H10: Liability | I10: Asset | J10: Owner's equity | K10: C | L10: Assets and expenses increase with debits. Revenue, liabilities, and equity increase with credits. | M10: Yes | N10: =IF(AND(M10="Yes",OR(QUIZ!$B$5="All Subjects",B10=QUIZ!$B$5),OR(QUIZ!$G$5="All Difficulties",E10=QUIZ!$G$5)),1,0) -> 0 | O10: =IF(N10=0,999999,MOD(IFERROR(VALUE(RIGHT(A10,3)),ROW())*7919+IF(N(QUIZ!$B$6)=0,1,QUIZ!$B$6)*104729+ROW()*IF(N(QUIZ!$B$6)=0,1,QUIZ!$B$6),999983)+ROW()/1000) -> 999999 | P10: =IF(N10=0,"",COUNTIFS($N$2:$N$510,1,$O$2:$O$510,"<"&O10)+1)
A11: Q010 | B11: Accounting | C11: Journal Entries | D11: Adjusting Entries | E11: Medium | F11: The adjusting entry for equipment depreciation includes a debit to: | G11: Equipment | H11: Accumulated depreciation | I11: Depreciation expense | J11: Cash | K11: C | L11: Debit depreciation expense and credit accumulated depreciation. | M11: Yes | N11: =IF(AND(M11="Yes",OR(QUIZ!$B$5="All Subjects",B11=QUIZ!$B$5),OR(QUIZ!$G$5="All Difficulties",E11=QUIZ!$G$5)),1,0) -> 0 | O11: =IF(N11=0,999999,MOD(IFERROR(VALUE(RIGHT(A11,3)),ROW())*7919+IF(N(QUIZ!$B$6)=0,1,QUIZ!$B$6)*104729+ROW()*IF(N(QUIZ!$B$6)=0,1,QUIZ!$B$6),999983)+ROW()/1000) -> 999999 | P11: =IF(N11=0,"",COUNTIFS($N$2:$N$510,1,$O$2:$O$510,"<"&O11)+1)
A12: Q011 | B12: Accounting | C12: Financial Statements | D12: Balance Sheet | E12: Easy | F12: The basic accounting equation is: | G12: Assets = Liabilities − Equity | H12: Assets = Liabilities + Equity | I12: Assets + Liabilities = Equity | J12: Revenue = Expenses + Equity | K12: B | L12: Assets equal liabilities plus equity. | M12: Yes | N12: =IF(AND(M12="Yes",OR(QUIZ!$B$5="All Subjects",B12=QUIZ!$B$5),OR(QUIZ!$G$5="All Difficulties",E12=QUIZ!$G$5)),1,0) -> 0 | O12: =IF(N12=0,999999,MOD(IFERROR(VALUE(RIGHT(A12,3)),ROW())*7919+IF(N(QUIZ!$B$6)=0,1,QUIZ!$B$6)*104729+ROW()*IF(N(QUIZ!$B$6)=0,1,QUIZ!$B$6),999983)+ROW()/1000) -> 999999 | P12: =IF(N12=0,"",COUNTIFS($N$2:$N$510,1,$O$2:$O$510,"<"&O12)+1)
A13: Q012 | B13: Accounting | C13: Financial Statements | D13: Income Statement | E13: Medium | F13: Gross profit equals: | G13: Sales − operating expenses | H13: Sales − cost of goods sold | I13: Net income + tax | J13: Assets − liabilities | K13: B | L13: Gross profit is sales minus cost of goods sold. | M13: Yes | N13: =IF(AND(M13="Yes",OR(QUIZ!$B$5="All Subjects",B13=QUIZ!$B$5),OR(QUIZ!$G$5="All Difficulties",E13=QUIZ!$G$5)),1,0) -> 0 | O13: =IF(N13=0,999999,MOD(IFERROR(VALUE(RIGHT(A13,3)),ROW())*7919+IF(N(QUIZ!$B$6)=0,1,QUIZ!$B$6)*104729+ROW()*IF(N(QUIZ!$B$6)=0,1,QUIZ!$B$6),999983)+ROW()/1000) -> 999999 | P13: =IF(N13=0,"",COUNTIFS($N$2:$N$510,1,$O$2:$O$510,"<"&O13)+1)
... A50: Q049 | B50: Excel | C50: Pivot Tables | D50: Summaries | E50: Hard | F50: A PivotTable calculated field: | G50: Changes the workbook file type | H50: Creates a formula from other pivot fields | I50: Deletes the pivot cache | J50: Requires a macro | K50: B | L50: A calculated field is a formula built from fields already in the pivot cache. | M50: Yes | N50: =IF(AND(M50="Yes",OR(QUIZ!$B$5="All Subjects",B50=QUIZ!$B$5),OR(QUIZ!$G$5="All Difficulties",E50=QUIZ!$G$5)),1,0) -> 0 | O50: =IF(N50=0,999999,MOD(IFERROR(VALUE(RIGHT(A50,3)),ROW())*7919+IF(N(QUIZ!$B$6)=0,1,QUIZ!$B$6)*104729+ROW()*IF(N(QUIZ!$B$6)=0,1,QUIZ!$B$6),999983)+ROW()/1000) -> 999999 | P50: =IF(N50=0,"",COUNTIFS($N$2:$N$510,1,$O$2:$O$510,"<"&O50)+1)
A51: MATH001 | B51: Mathematics | C51: Calculus | D51: Integration | E51: Medium | F51: Using substitution, evaluate the indefinite integral of 2x(x^2+1)^3. | G51: (x^2+1)^4 / 4 + C | H51: (x^2+1)^3 / 3 + C | I51: 2(x^2+1)^4 + C | J51: x^2(x^2+1)^4 + C | K51: A | L51: Let u = x^2+1, so du = 2x dx. The integral is u^4/4 + C. | M51: Yes | N51: =IF(AND(M51="Yes",OR(QUIZ!$B$5="All Subjects",B51=QUIZ!$B$5),OR(QUIZ!$G$5="All Difficulties",E51=QUIZ!$G$5)),1,0) -> 1 | O51: =IF(N51=0,999999,MOD(IFERROR(VALUE(RIGHT(A51,3)),ROW())*7919+IF(N(QUIZ!$B$6)=0,1,QUIZ!$B$6)*104729+ROW()*IF(N(QUIZ!$B$6)=0,1,QUIZ!$B$6),999983)+ROW()/1000) -> 112699.05 | P51: =IF(N51=0,"",COUNTIFS($N$2:$N$500,1,$O$2:$O$500,"<"&O51)+1) -> 1
A52: MATH002 | B52: Mathematics | C52: Calculus | D52: Integration | E52: Medium | F52: Using substitution, evaluate the indefinite integral of 2x e^(x^2). | G52: e^(x^2) + C | H52: 2e^(x^2) + C | I52: x e^(x^2) + C | J52: e^(2x) + C | K52: A | L52: Let u = x^2, so du = 2x dx. The integral is e^u + C = e^(x^2) + C. | M52: Yes | N52: =IF(AND(M52="Yes",OR(QUIZ!$B$5="All Subjects",B52=QUIZ!$B$5),OR(QUIZ!$G$5="All Difficulties",E52=QUIZ!$G$5)),1,0) -> 1 | O52: =IF(N52=0,999999,MOD(IFERROR(VALUE(RIGHT(A52,3)),ROW())*7919+IF(N(QUIZ!$B$6)=0,1,QUIZ!$B$6)*104729+ROW()*IF(N(QUIZ!$B$6)=0,1,QUIZ!$B$6),999983)+ROW()/1000) -> 120619.05 | P52: =IF(N52=0,"",COUNTIFS($N$2:$N$500,1,$O$2:$O$500,"<"&O52)+1) -> 3
A53: MATH003 | B53: Mathematics | C53: Calculus | D53: Integration | E53: Medium | F53: Evaluate the definite integral of 2x from 0 to 1. | G53: 1 | H53: 2 | I53: 0 | J53: 1/2 | K53: A | L53: The antiderivative is x^2. From 0 to 1 this is 1 - 0 = 1. | M53: Yes | N53: =IF(AND(M53="Yes",OR(QUIZ!$B$5="All Subjects",B53=QUIZ!$B$5),OR(QUIZ!$G$5="All Difficulties",E53=QUIZ!$G$5)),1,0) -> 1 | O53: =IF(N53=0,999999,MOD(IFERROR(VALUE(RIGHT(A53,3)),ROW())*7919+IF(N(QUIZ!$B$6)=0,1,QUIZ!$B$6)*104729+ROW()*IF(N(QUIZ!$B$6)=0,1,QUIZ!$B$6),999983)+ROW()/1000) -> 128539.05 | P53: =IF(N53=0,"",COUNTIFS($N$2:$N$500,1,$O$2:$O$500,"<"&O53)+1) -> 4
A54: MATH004 | B54: Mathematics | C54: Calculus | D54: Integration | E54: Medium | F54: Evaluate the definite integral of 3x^2 from 0 to 2. | G54: 8 | H54: 12 | I54: 4 | J54: 6 | K54: A | L54: The antiderivative is x^3. At 2 this is 8, and at 0 it is 0. | M54: Yes | N54: =IF(AND(M54="Yes",OR(QUIZ!$B$5="All Subjects",B54=QUIZ!$B$5),OR(QUIZ!$G$5="All Difficulties",E54=QUIZ!$G$5)),1,0) -> 1 | O54: =IF(N54=0,999999,MOD(IFERROR(VALUE(RIGHT(A54,3)),ROW())*7919+IF(N(QUIZ!$B$6)=0,1,QUIZ!$B$6)*104729+ROW()*IF(N(QUIZ!$B$6)=0,1,QUIZ!$B$6),999983)+ROW()/1000) -> 136459.05 | P54: =IF(N54=0,"",COUNTIFS($N$2:$N$500,1,$O$2:$O$500,"<"&O54)+1) -> 6
A55: MATH005 | B55: Mathematics | C55: Calculus | D55: Integration | E55: Medium | F55: Using substitution, evaluate the indefinite integral of 2x/(x^2+1). | G55: ln|x^2+1| + C | H55: 2 ln|x^2+1| + C | I55: ln|2x| + C | J55: arctan(x^2) + C | K55: A | L55: Let u = x^2+1, so du = 2x dx. The integral is ln|u| + C. | M55: Yes | N55: =IF(AND(M55="Yes",OR(QUIZ!$B$5="All Subjects",B55=QUIZ!$B$5),OR(QUIZ!$G$5="All Difficulties",E55=QUIZ!$G$5)),1,0) -> 1 | O55: =IF(N55=0,999999,MOD(IFERROR(VALUE(RIGHT(A55,3)),ROW())*7919+IF(N(QUIZ!$B$6)=0,1,QUIZ!$B$6)*104729+ROW()*IF(N(QUIZ!$B$6)=0,1,QUIZ!$B$6),999983)+ROW()/1000) -> 144379.05 | P55: =IF(N55=0,"",COUNTIFS($N$2:$N$500,1,$O$2:$O$500,"<"&O55)+1) -> 7
A56: MATH006 | B56: Mathematics | C56: Calculus | D56: Integration | E56: Medium | F56: Evaluate the definite integral of 1/x from 1 to e. | G56: 1 | H56: e | I56: 0 | J56: e-1 | K56: A | L56: The antiderivative is ln|x|. ln(e) - ln(1) = 1 - 0 = 1. | M56: Yes | N56: =IF(AND(M56="Yes",OR(QUIZ!$B$5="All Subjects",B56=QUIZ!$B$5),OR(QUIZ!$G$5="All Difficulties",E56=QUIZ!$G$5)),1,0) -> 1 | O56: =IF(N56=0,999999,MOD(IFERROR(VALUE(RIGHT(A56,3)),ROW())*7919+IF(N(QUIZ!$B$6)=0,1,QUIZ!$B$6)*104729+ROW()*IF(N(QUIZ!$B$6)=0,1,QUIZ!$B$6),999983)+ROW()/1000) -> 152299.06 | P56: =IF(N56=0,"",COUNTIFS($N$2:$N$500,1,$O$2:$O$500,"<"&O56)+1) -> 9
A57: MATH007 | B57: Mathematics | C57: Calculus | D57: Integration | E57: Medium | F57: Using the substitution u = sin(x), evaluate the indefinite integral of sin(x)cos(x). | G57: (1/2) sin^2(x) + C | H57: sin^2(x) + C | I57: cos^2(x) + C | J57: negative cos(x) + C | K57: A | L57: du = cos(x) dx, so the integral is u^2/2 + C = (1/2) sin^2(x) + C. | M57: Yes | N57: =IF(AND(M57="Yes",OR(QUIZ!$B$5="All Subjects",B57=QUIZ!$B$5),OR(QUIZ!$G$5="All Difficulties",E57=QUIZ!$G$5)),1,0) -> 1 | O57: =IF(N57=0,999999,MOD(IFERROR(VALUE(RIGHT(A57,3)),ROW())*7919+IF(N(QUIZ!$B$6)=0,1,QUIZ!$B$6)*104729+ROW()*IF(N(QUIZ!$B$6)=0,1,QUIZ!$B$6),999983)+ROW()/1000) -> 160219.06 | P57: =IF(N57=0,"",COUNTIFS($N$2:$N$500,1,$O$2:$O$500,"<"&O57)+1) -> 10
A58: MATH008 | B58: Mathematics | C58: Calculus | D58: Integration | E58: Medium | F58: Using substitution, evaluate the definite integral of 2x(x^2+1)^2 from 0 to 1. | G58: 7/3 | H58: 3 | I58: 1 | J58: 8/3 | K58: A | L58: Let u = x^2+1. Limits change from 1 to 2. The integral of u^2 is 8/3 - 1/3 = 7/3. | M58: Yes | N58: =IF(AND(M58="Yes",OR(QUIZ!$B$5="All Subjects",B58=QUIZ!$B$5),OR(QUIZ!$G$5="All Difficulties",E58=QUIZ!$G$5)),1,0) -> 1 | O58: =IF(N58=0,999999,MOD(IFERROR(VALUE(RIGHT(A58,3)),ROW())*7919+IF(N(QUIZ!$B$6)=0,1,QUIZ!$B$6)*104729+ROW()*IF(N(QUIZ!$B$6)=0,1,QUIZ!$B$6),999983)+ROW()/1000) -> 168139.06 | P58: =IF(N58=0,"",COUNTIFS($N$2:$N$500,1,$O$2:$O$500,"<"&O58)+1) -> 12
A59: MATH009 | B59: Mathematics | C59: Calculus | D59: Integration | E59: Medium | F59: Using substitution, evaluate the indefinite integral of x / sqrt(x^2+1). | G59: sqrt(x^2+1) + C | H59: 2 sqrt(x^2+1) + C | I59: ln|x^2+1| + C | J59: (x^2+1)^(3/2) / 3 + C | K59: A | L59: Let u = x^2+1, so du = 2x dx and x dx = du/2. The integral is sqrt(u) + C. | M59: Yes | N59: =IF(AND(M59="Yes",OR(QUIZ!$B$5="All Subjects",B59=QUIZ!$B$5),OR(QUIZ!$G$5="All Difficulties",E59=QUIZ!$G$5)),1,0) -> 1 | O59: =IF(N59=0,999999,MOD(IFERROR(VALUE(RIGHT(A59,3)),ROW())*7919+IF(N(QUIZ!$B$6)=0,1,QUIZ!$B$6)*104729+ROW()*IF(N(QUIZ!$B$6)=0,1,QUIZ!$B$6),999983)+ROW()/1000) -> 176059.06 | P59: =IF(N59=0,"",COUNTIFS($N$2:$N$500,1,$O$2:$O$500,"<"&O59)+1) -> 13
A60: MATH010 | B60: Mathematics | C60: Calculus | D60: Integration | E60: Medium | F60: Evaluate the definite integral of cos(x) from 0 to pi/2. | G60: 1 | H60: 0 | I60: pi/2 | J60: negative 1 | K60: A | L60: The antiderivative is sin(x). sin(pi/2) - sin(0) = 1 - 0 = 1. | M60: Yes | N60: =IF(AND(M60="Yes",OR(QUIZ!$B$5="All Subjects",B60=QUIZ!$B$5),OR(QUIZ!$G$5="All Difficulties",E60=QUIZ!$G$5)),1,0) -> 1 | O60: =IF(N60=0,999999,MOD(IFERROR(VALUE(RIGHT(A60,3)),ROW())*7919+IF(N(QUIZ!$B$6)=0,1,QUIZ!$B$6)*104729+ROW()*IF(N(QUIZ!$B$6)=0,1,QUIZ!$B$6),999983)+ROW()/1000) -> 183979.06 | P60: =IF(N60=0,"",COUNTIFS($N$2:$N$500,1,$O$2:$O$500,"<"&O60)+1) -> 14

Sheet AI QUESTION GENERATOR
A1: AI QUESTION GENERATOR | Z1: Subject | AA1: Prefix
A2: Build a copy-ready prompt, ask an AI for tab-separated rows, then paste those rows at the bottom of tblQuestions. | Z2: Mathematics | AA2: MATH
A3: SUBJECT | B3: Mathematics | Z3: Accounting | AA3: ACC
A4: TOPIC | B4: Calculus | Z4: Economics | AA4: ECO
A5: SUBTOPIC | B5: Integration | Z5: Excel | AA5: XLS
A6: DIFFICULTY | B6: Medium | Z6: PowerPoint | AA6: PPT
A7: NUMBER OF QUESTIONS | B7: 10 | Z7: Business Studies | AA7: BUS
A8: QUESTION TYPE | B8: Multiple Choice | Z8: English | AA8: ENG
A9: TARGET QUESTION IDs | B9: {=_xlfn.LET(_xlpm.pfx,IF(B3="","OTH",IFERROR(_xlfn.XLOOKUP(B3,$Z$2:$Z$10,$AA$2:$AA$10),UPPER(LEFT(SUBSTITUTE(B3," ",""),3)))), _xlpm.n,IFERROR(MAX(VALUE(RIGHT(_xlfn._xlws.FILTER(tblQuestions[Question ID],LEFT(tblQuestions[Question ID],LEN(_xlpm.pfx))=_xlpm.pfx),3))),0)+1, _xlpm.pfx&TEXT(_xlpm.n,"000")&" to "&_xlpm.pfx&TEXT(_xlpm.n+MAX(B7,1)-1,"000"))} -> MATH011 to MATH020 | D9: {=_xlfn.LET(_xlpm.pfx,IF(B3="","OTH",IFERROR(_xlfn.XLOOKUP(B3,$Z$2:$Z$10,$AA$2:$AA$10),UPPER(LEFT(SUBSTITUTE(B3," ",""),3)))), _xlpm.n,IFERROR(MAX(VALUE(RIGHT(_xlfn._xlws.FILTER(tblQuestions[Question ID],LEFT(tblQuestions[Question ID],LEN(_xlpm.pfx))=_xlpm.pfx),3))),0)+1, _xlpm.pfx&TEXT(_xlpm.n,"000"))} -> MATH011 | Z9: Computer Applications | AA9: CAP
A10: GENERATED QUESTION STYLE | B10: Exam Style | Z10: Other | AA10: OTH
A11: SPECIAL INSTRUCTIONS | B11: Focus on integration by substitution and basic definite integrals.
A16: GENERATED AI PROMPT
A17: {=_xlfn.CONCAT("Generate new questions for my Excel AI Study Assistant.",CHAR(10),CHAR(10),"Subject: ",B3,CHAR(10),"Topic: ",B4,CHAR(10),"Subtopic: ",B5,CHAR(10),"Difficulty: ",B6,CHAR(10),"Number of questions: ",B7,CHAR(10),"Question type: ",B8,CHAR(10),"Question style: ",B10,CHAR(10),"Starting Question ID: ",D9,CHAR(10),"Ending Question ID: ",_xlfn.LET(_xlpm.pfx,LEFT(D9,LEN(D9)-3), _xlpm.n, VALUE(RIGHT(D9,3)), _xlpm.pfx&TEXT(_xlpm.n+MAX(B7,1)-1,"000")),CHAR(10),"Special instructions: ",B11,CHAR(10),CHAR(10),"CRITICAL INSTRUCTIONS",CHAR(10),"1. Generate exactly the requested number of questions.",CHAR(10),"2. Every question must be multiple choice.",CHAR(10),"3. Every question must have exactly four options: A, B, C, and D.",CHAR(10),"4. Exactly ONE option must be correct.",CHAR(10),"5. Provide the correct answer.",CHAR(10),"6. Provide a concise explanation.",CHAR(10),"7. Questions must be factually accurate.",CHAR(10),"8. Questions must match the requested subject, topic, subtopic, and difficulty. If difficulty is Mixed, spread Easy, Medium, and Hard.",CHAR(10),"9. Do not create duplicate questions.",CHAR(10),"10. Do not create questions that are merely reworded versions of each other.",CHAR(10),"11. Use different concepts and calculations whenever possible.",CHAR(10),"12. Make incorrect options plausible rather than obviously wrong.",CHAR(10),"13. For numerical questions, independently calculate and verify the answer.",CHAR(10),"14. Do not include answers inside the question text.",CHAR(10),"15. Do not use question numbers such as Question 1 inside the question text.",CHAR(10),"16. Generate unique Question IDs, starting at ",D9," and increasing by 1.",CHAR(10),"17. Do not reuse Question IDs that already exist in QUESTION_BANK.",CHAR(10),"18. Keep explanations short but useful.",CHAR(10),"19. Do not include Markdown tables.",CHAR(10),"20. Do not include headings, introductions, explanations, or extra text around the data.",CHAR(10),"21. Return ONLY the data rows in the exact requested format.",CHAR(10),CHAR(10),"EXACT OUTPUT FORMAT",CHAR(10),"Return TAB-SEPARATED VALUES with exactly these columns, in this order:",CHAR(10),"Question ID, Subject, Topic, Subtopic, Difficulty, Question, Option A, Option B, Option C, Option D, Correct Answer, Explanation, Active",CHAR(10),"Correct Answer must be only A, B, C, or D. Set Active to Yes on every row.",CHAR(10),"Example (tabs, not spaces):",CHAR(10),D9,CHAR(9),B3,CHAR(9),B4,CHAR(9),B5,CHAR(9),IF(B6="Mixed","Medium",B6),CHAR(9),"What is the integral of 2x?",CHAR(9),"x^2 + C",CHAR(9),"2x^2 + C",CHAR(9),"x + C",CHAR(9),"2 + C",CHAR(9),"A",CHAR(9),"The integral of 2x is x^2 + C.",CHAR(9),"Yes",CHAR(10),CHAR(10),"Do NOT add Markdown tables, numbering, bullets, extra columns, blank rows, commentary, or code fences.",CHAR(10),"The rows will be pasted directly underneath the existing records in tblQuestions. Keep this exact column order:",CHAR(10),"A Question ID, B Subject, C Topic, D Subtopic, E Difficulty, F Question, G Option A, H Option B, I Option C, J Option D, K Correct Answer, L Explanation, M Active.",CHAR(10),CHAR(10),"If I provide an existing-question list after this prompt, compare against it and do not repeat or closely reword those questions.",CHAR(10),CHAR(10),"EXISTING QUESTION IDS",CHAR(10),_xlfn.TEXTJOIN(", ",TRUE,tblQuestions[Question ID]),CHAR(10),CHAR(10),"EXISTING QUESTIONS FOR THIS SUBJECT — do not repeat or closely reword these:",CHAR(10),IFERROR(_xlfn.TEXTJOIN(CHAR(10),TRUE,_xlfn._xlws.FILTER(tblQuestions[Question ID]&" | "&tblQuestions[Question],tblQuestions[Subject]=B3)),"None yet for this subject."))} -> Generate new questions for my Excel AI Study Assistant. Subject: Mathematics Topic: Calculus Subtopic: Integration Difficulty: Medium Number of questions: 10 Question type: Multiple Choice Question style: Exam Style Starting Question ID: MATH011 Ending Question ID: MATH020 Special instructions: Focus on integration by substitution and basic definite integrals. CRITICAL INSTRUCTIONS 1. Generate exactly the requested number of questions. 2. Every question must be multiple choice. 3. Every question must have exactly four options: A, B, C, and D. 4. Exactly ONE option must be correct. 5. Provide the correct answer. 6. Provide a concise explanation. 7. Questions must be factually accurate. 8. Questions must match the requested subject, topic, subtopic, and difficulty. If difficulty is Mixed, spread Easy, Medium, and Hard. 9. Do not create duplicate questions. 10. Do not create questions that are merely reworded versions of each other. 11. Use different concepts and calculations whenever possible. 12. Make incorrect options plausible rather than obviously wrong. 13. For numerical questions, independently calculate and verify the answer. 14. Do not include answers inside the question text. 15. Do not use question numbers such as Question 1 inside the question text. 16. Generate unique Question IDs, starting at MATH011 and increasing by 1. 17. Do not reuse Question IDs that already exist in QUESTION_BANK. 18. Keep explanations short but useful. 19. Do not include Markdown tables. 20. Do not include headings, introductions, explanations, or extra text around the data. 21. Return ONLY the data rows in the exact requested format. EXACT OUTPUT FORMAT Return TAB-SEPARATED VALUES with exactly these columns, in this order: Question ID, Subject, Topic, Subtopic, Difficulty, Question, Option A, Option B, Option C, Option D, Correct Answer, Explanation, Active Correct Answer must be only A, B, C, or D. Set Active to Yes on every row. Example (tabs, not spaces): MATH011 Mathematics Calculus Integration Medium What is the integral of 2x? x^2 + C 2x^2 + C x + C 2 + C A The integral of 2x is x^2 + C. Yes Do NOT add Markdown tables, numbering, bullets, extra columns, blank rows, commentary, or code fences. The rows will be pasted directly underneath the existing records in tblQuestions. Keep this exact column order: A Question ID, B Subject, C Topic, D Subtopic, E Difficulty, F Question, G Option A, H Option B, I Option C, J Option D, K Correct Answer, L Explanation, M Active. If I provide an existing-question list after this prompt, compare against it and do not repeat or closely reword those questions. EXISTING QUESTION IDS Q001, Q002, Q003, Q004, Q005, Q006, Q007, Q008, Q009, Q010, Q011, Q012, Q013, Q014, Q015, Q016, Q017, Q018, Q019, Q020, Q021, Q022, Q023, Q024, Q025, Q026, Q027, Q028, Q029, Q030, Q031, Q032, Q033, Q034, Q035, Q036, Q037, Q038, Q039, Q040, Q041, Q042, Q043, Q044, Q045, Q046, Q047, Q048, Q049, MATH001, MATH002, MATH003, MATH004, MATH005, MATH006, MATH007, MATH008, MATH009, MATH010 EXISTING QUESTIONS FOR THIS SUBJECT — do not repeat or closely reword these: Q001 | What is the derivative of x²? Q002 | What is the derivative of sin(x)? Q003 | What is the indefinite integral of 2x? Q004 | What is the indefinite integral of 1/x? Q005 | Solve 2x + 3 = 11. Q006 | What are the roots of x² − 5x + 6 = 0? Q007 | What is the mean of 2, 4, 6, and 8? Q008 | A fair coin is flipped twice. What is the probability of two heads? Q037 | What is 10% of 200? Q039 | What is 15% of 80? Q040 | The median of 3, 9, and 4 is: MATH001 | Using substitution, evaluate the indefinite integral of 2x(x^2+1)^3. MATH002 | Using substitution, evaluate the indefinite integral of 2x e^(x^2). MATH003 | Evaluate the definite integral of 2x from 0 to 1. MATH004 | Evaluate the definite integral of 3x^2 from 0 to 2. MATH005 | Using substitution, evaluate the indefinite integral of 2x/(x^2+1). MATH006 | Evaluate the definite integral of 1/x from 1 to e. MATH007 | Using the substitution u = sin(x), evaluate the indefinite integral of sin(x)cos(x). MATH008 | Using substitution, evaluate the definite integral of 2x(x^2+1)^2 from 0 to 1. MATH009 | Using substitution, evaluate the indefinite integral of x / sqrt(x^2+1). MATH010 | Evaluate the definite integral of cos(x) from 0 to pi/2.
A30: PASTE GENERATED QUESTIONS HERE
A31: Excel 2021 cannot import this automatically. 1) Fill the blue inputs. 2) Copy the GENERATED AI PROMPT. 3) Give it to Grok or another AI. 4) Copy the tab-separated rows. 5) Paste them directly under the last row of tblQuestions on QUESTION_BANK. The table and quiz pick up new Active = Yes rows. The grid below is only a staging check, not a second database.
A34: Question ID | B34: Subject | C34: Topic | D34: Subtopic | E34: Difficulty | F34: Question | G34: Option A | H34: Option B | I34: Option C | J34: Option D | K34: Correct Answer | L34: Explanation | M34: Active
A36: LATEST QUESTIONS IN QUESTION_BANK
A37: Question ID | B37: Subject | C37: Topic | D37: Difficulty | E37: Question | F37: Correct Answer
A38: {=IFERROR(INDEX(tblQuestions[Question ID],ROWS(tblQuestions[Question ID])-9),"")} -> MATH001 | B38: =IF(A38="","",_xlfn.XLOOKUP(A38,tblQuestions[Question ID],tblQuestions[Subject])) -> Mathematics | C38: =IF(A38="","",_xlfn.XLOOKUP(A38,tblQuestions[Question ID],tblQuestions[Topic])) -> Calculus | D38: =IF(A38="","",_xlfn.XLOOKUP(A38,tblQuestions[Question ID],tblQuestions[Difficulty])) -> Medium | E38: =IF(A38="","",_xlfn.XLOOKUP(A38,tblQuestions[Question ID],tblQuestions[Question])) -> Using substitution, evaluate the indefinite integral of 2x(x^2+1)^3. | F38: =IF(A38="","",_xlfn.XLOOKUP(A38,tblQuestions[Question ID],tblQuestions[Correct Answer])) -> A
A39: {=IFERROR(INDEX(tblQuestions[Question ID],ROWS(tblQuestions[Question ID])-8),"")} -> MATH002 | B39: =IF(A39="","",_xlfn.XLOOKUP(A39,tblQuestions[Question ID],tblQuestions[Subject])) -> Mathematics | C39: =IF(A39="","",_xlfn.XLOOKUP(A39,tblQuestions[Question ID],tblQuestions[Topic])) -> Calculus | D39: =IF(A39="","",_xlfn.XLOOKUP(A39,tblQuestions[Question ID],tblQuestions[Difficulty])) -> Medium | E39: =IF(A39="","",_xlfn.XLOOKUP(A39,tblQuestions[Question ID],tblQuestions[Question])) -> Using substitution, evaluate the indefinite integral of 2x e^(x^2). | F39: =IF(A39="","",_xlfn.XLOOKUP(A39,tblQuestions[Question ID],tblQuestions[Correct Answer])) -> A
A40: {=IFERROR(INDEX(tblQuestions[Question ID],ROWS(tblQuestions[Question ID])-7),"")} -> MATH003 | B40: =IF(A40="","",_xlfn.XLOOKUP(A40,tblQuestions[Question ID],tblQuestions[Subject])) -> Mathematics | C40: =IF(A40="","",_xlfn.XLOOKUP(A40,tblQuestions[Question ID],tblQuestions[Topic])) -> Calculus | D40: =IF(A40="","",_xlfn.XLOOKUP(A40,tblQuestions[Question ID],tblQuestions[Difficulty])) -> Medium | E40: =IF(A40="","",_xlfn.XLOOKUP(A40,tblQuestions[Question ID],tblQuestions[Question])) -> Evaluate the definite integral of 2x from 0 to 1. | F40: =IF(A40="","",_xlfn.XLOOKUP(A40,tblQuestions[Question ID],tblQuestions[Correct Answer])) -> A
A41: {=IFERROR(INDEX(tblQuestions[Question ID],ROWS(tblQuestions[Question ID])-6),"")} -> MATH004 | B41: =IF(A41="","",_xlfn.XLOOKUP(A41,tblQuestions[Question ID],tblQuestions[Subject])) -> Mathematics | C41: =IF(A41="","",_xlfn.XLOOKUP(A41,tblQuestions[Question ID],tblQuestions[Topic])) -> Calculus | D41: =IF(A41="","",_xlfn.XLOOKUP(A41,tblQuestions[Question ID],tblQuestions[Difficulty])) -> Medium | E41: =IF(A41="","",_xlfn.XLOOKUP(A41,tblQuestions[Question ID],tblQuestions[Question])) -> Evaluate the definite integral of 3x^2 from 0 to 2. | F41: =IF(A41="","",_xlfn.XLOOKUP(A41,tblQuestions[Question ID],tblQuestions[Correct Answer])) -> A
A42: {=IFERROR(INDEX(tblQuestions[Question ID],ROWS(tblQuestions[Question ID])-5),"")} -> MATH005 | B42: =IF(A42="","",_xlfn.XLOOKUP(A42,tblQuestions[Question ID],tblQuestions[Subject])) -> Mathematics | C42: =IF(A42="","",_xlfn.XLOOKUP(A42,tblQuestions[Question ID],tblQuestions[Topic])) -> Calculus | D42: =IF(A42="","",_xlfn.XLOOKUP(A42,tblQuestions[Question ID],tblQuestions[Difficulty])) -> Medium | E42: =IF(A42="","",_xlfn.XLOOKUP(A42,tblQuestions[Question ID],tblQuestions[Question])) -> Using substitution, evaluate the indefinite integral of 2x/(x^2+1). | F42: =IF(A42="","",_xlfn.XLOOKUP(A42,tblQuestions[Question ID],tblQuestions[Correct Answer])) -> A
A43: {=IFERROR(INDEX(tblQuestions[Question ID],ROWS(tblQuestions[Question ID])-4),"")} -> MATH006 | B43: =IF(A43="","",_xlfn.XLOOKUP(A43,tblQuestions[Question ID],tblQuestions[Subject])) -> Mathematics | C43: =IF(A43="","",_xlfn.XLOOKUP(A43,tblQuestions[Question ID],tblQuestions[Topic])) -> Calculus | D43: =IF(A43="","",_xlfn.XLOOKUP(A43,tblQuestions[Question ID],tblQuestions[Difficulty])) -> Medium | E43: =IF(A43="","",_xlfn.XLOOKUP(A43,tblQuestions[Question ID],tblQuestions[Question])) -> Evaluate the definite integral of 1/x from 1 to e. | F43: =IF(A43="","",_xlfn.XLOOKUP(A43,tblQuestions[Question ID],tblQuestions[Correct Answer])) -> A
A44: {=IFERROR(INDEX(tblQuestions[Question ID],ROWS(tblQuestions[Question ID])-3),"")} -> MATH007 | B44: =IF(A44="","",_xlfn.XLOOKUP(A44,tblQuestions[Question ID],tblQuestions[Subject])) -> Mathematics | C44: =IF(A44="","",_xlfn.XLOOKUP(A44,tblQuestions[Question ID],tblQuestions[Topic])) -> Calculus | D44: =IF(A44="","",_xlfn.XLOOKUP(A44,tblQuestions[Question ID],tblQuestions[Difficulty])) -> Medium | E44: =IF(A44="","",_xlfn.XLOOKUP(A44,tblQuestions[Question ID],tblQuestions[Question])) -> Using the substitution u = sin(x), evaluate the indefinite integral of sin(x)cos(x). | F44: =IF(A44="","",_xlfn.XLOOKUP(A44,tblQuestions[Question ID],tblQuestions[Correct Answer])) -> A
A45: {=IFERROR(INDEX(tblQuestions[Question ID],ROWS(tblQuestions[Question ID])-2),"")} -> MATH008 | B45: =IF(A45="","",_xlfn.XLOOKUP(A45,tblQuestions[Question ID],tblQuestions[Subject])) -> Mathematics | C45: =IF(A45="","",_xlfn.XLOOKUP(A45,tblQuestions[Question ID],tblQuestions[Topic])) -> Calculus | D45: =IF(A45="","",_xlfn.XLOOKUP(A45,tblQuestions[Question ID],tblQuestions[Difficulty])) -> Medium | E45: =IF(A45="","",_xlfn.XLOOKUP(A45,tblQuestions[Question ID],tblQuestions[Question])) -> Using substitution, evaluate the definite integral of 2x(x^2+1)^2 from 0 to 1. | F45: =IF(A45="","",_xlfn.XLOOKUP(A45,tblQuestions[Question ID],tblQuestions[Correct Answer])) -> A
A46: {=IFERROR(INDEX(tblQuestions[Question ID],ROWS(tblQuestions[Question ID])-1),"")} -> MATH009 | B46: =IF(A46="","",_xlfn.XLOOKUP(A46,tblQuestions[Question ID],tblQuestions[Subject])) -> Mathematics | C46: =IF(A46="","",_xlfn.XLOOKUP(A46,tblQuestions[Question ID],tblQuestions[Topic])) -> Calculus | D46: =IF(A46="","",_xlfn.XLOOKUP(A46,tblQuestions[Question ID],tblQuestions[Difficulty])) -> Medium | E46: =IF(A46="","",_xlfn.XLOOKUP(A46,tblQuestions[Question ID],tblQuestions[Question])) -> Using substitution, evaluate the indefinite integral of x / sqrt(x^2+1). | F46: =IF(A46="","",_xlfn.XLOOKUP(A46,tblQuestions[Question ID],tblQuestions[Correct Answer])) -> A
A47: {=IFERROR(INDEX(tblQuestions[Question ID],ROWS(tblQuestions[Question ID])-0),"")} -> MATH010 | B47: =IF(A47="","",_xlfn.XLOOKUP(A47,tblQuestions[Question ID],tblQuestions[Subject])) -> Mathematics | C47: =IF(A47="","",_xlfn.XLOOKUP(A47,tblQuestions[Question ID],tblQuestions[Topic])) -> Calculus | D47: =IF(A47="","",_xlfn.XLOOKUP(A47,tblQuestions[Question ID],tblQuestions[Difficulty])) -> Medium | E47: =IF(A47="","",_xlfn.XLOOKUP(A47,tblQuestions[Question ID],tblQuestions[Question])) -> Evaluate the definite integral of cos(x) from 0 to pi/2. | F47: =IF(A47="","",_xlfn.XLOOKUP(A47,tblQuestions[Question ID],tblQuestions[Correct Answer])) -> A
A48: ← HOME | C48: QUESTION BANK

Sheet RESULTS
A1: QUIZ RESULTS
A2: Review the current quiz, see the score, and find the weakest subtopic.
A3: ← HOME | E3: → PROGRESS
A5: SUMMARY | F5: PERFORMANCE
A6: Subject | B6: =IF(QUIZ!AA3=0,"-",QUIZ!B5) -> Mathematics | F6: =IF(QUIZ!O6=0,"Take a quiz to see a performance message.",IF(QUIZ!O12>=0.9,"Excellent! You have a strong understanding of this material.",IF(QUIZ!O12>=0.75,"Very good! A little more practice can make your performance even stronger.",IF(QUIZ!O12>=0.5,"Good attempt. Review the weaker areas and try another quiz.","Focus on the fundamentals and review the weak topics before attempting another quiz.")))) -> Focus on the fundamentals and review the weak topics before attempting another quiz.
A7: Difficulty | B7: =IF(QUIZ!AA3=0,"-",QUIZ!G5) -> Medium
A8: Questions | B8: =QUIZ!O6 -> 10
A9: Correct | B9: =QUIZ!O8 -> 0 | AA9: =IF(QUIZ!AA9="","",_xlfn.XLOOKUP(QUIZ!AA9,tblQuestions[Question ID],tblQuestions[Subtopic])) -> Integration
A10: Incorrect | B10: =QUIZ!O9 -> 0 | AA10: =IF(QUIZ!AA10="","",_xlfn.XLOOKUP(QUIZ!AA10,tblQuestions[Question ID],tblQuestions[Subtopic])) -> Derivatives
A11: Not Answered | B11: =QUIZ!O10 -> 10 | AA11: =IF(QUIZ!AA11="","",_xlfn.XLOOKUP(QUIZ!AA11,tblQuestions[Question ID],tblQuestions[Subtopic])) -> Integration
A12: Score | B12: =QUIZ!O11 -> 0 / 10 | AA12: =IF(QUIZ!AA12="","",_xlfn.XLOOKUP(QUIZ!AA12,tblQuestions[Question ID],tblQuestions[Subtopic])) -> Integration
A13: Accuracy | B13: =IF(QUIZ!O6=0,"-",QUIZ!O12) -> 0 | AA13: =IF(QUIZ!AA13="","",_xlfn.XLOOKUP(QUIZ!AA13,tblQuestions[Question ID],tblQuestions[Subtopic])) -> Integration
AA14: =IF(QUIZ!AA14="","",_xlfn.XLOOKUP(QUIZ!AA14,tblQuestions[Question ID],tblQuestions[Subtopic])) -> Integration
A15: WEAK TOPIC ANALYSIS | AA15: =IF(QUIZ!AA15="","",_xlfn.XLOOKUP(QUIZ!AA15,tblQuestions[Question ID],tblQuestions[Subtopic])) -> Integration
A16: Subtopic | B16: Questions | C16: Correct | D16: Accuracy | AA16: =IF(QUIZ!AA16="","",_xlfn.XLOOKUP(QUIZ!AA16,tblQuestions[Question ID],tblQuestions[Subtopic])) -> Quadratic Equations | AB16: {=IFERROR(_xlfn.UNIQUE(_xlfn._xlws.FILTER(AA9:AA28,AA9:AA28<>"")),"")} -> Integration
A17: {=IFERROR(IF(INDEX(_xlfn.ANCHORARRAY($AB$16),ROW()-16)="","",INDEX(_xlfn.ANCHORARRAY($AB$16),ROW()-16)),"")} -> Integration | B17: =IF(A17="","",COUNTIF($AA$9:$AA$28,A17)) -> 8 | C17: {=IF(A17="","",SUMPRODUCT(($AA$9:$AA$28=A17)*(QUIZ!$K$9:$K$28="CORRECT")))} -> 0 | D17: =IF(OR(A17="",B17=0),"",C17/B17) -> 0 | AA17: =IF(QUIZ!AA17="","",_xlfn.XLOOKUP(QUIZ!AA17,tblQuestions[Question ID],tblQuestions[Subtopic])) -> Integration | AB17: Derivatives
A18: {=IFERROR(IF(INDEX(_xlfn.ANCHORARRAY($AB$16),ROW()-16)="","",INDEX(_xlfn.ANCHORARRAY($AB$16),ROW()-16)),"")} -> Derivatives | B18: =IF(A18="","",COUNTIF($AA$9:$AA$28,A18)) -> 1 | C18: {=IF(A18="","",SUMPRODUCT(($AA$9:$AA$28=A18)*(QUIZ!$K$9:$K$28="CORRECT")))} -> 0 | D18: =IF(OR(A18="",B18=0),"",C18/B18) -> 0 | AA18: =IF(QUIZ!AA18="","",_xlfn.XLOOKUP(QUIZ!AA18,tblQuestions[Question ID],tblQuestions[Subtopic])) -> Integration | AB18: Quadratic Equations
A19: {=IFERROR(IF(INDEX(_xlfn.ANCHORARRAY($AB$16),ROW()-16)="","",INDEX(_xlfn.ANCHORARRAY($AB$16),ROW()-16)),"")} -> Quadratic Equations | B19: =IF(A19="","",COUNTIF($AA$9:$AA$28,A19)) -> 1 | C19: {=IF(A19="","",SUMPRODUCT(($AA$9:$AA$28=A19)*(QUIZ!$K$9:$K$28="CORRECT")))} -> 0 | D19: =IF(OR(A19="",B19=0),"",C19/B19) -> 0 | AA19: =IF(QUIZ!AA19="","",_xlfn.XLOOKUP(QUIZ!AA19,tblQuestions[Question ID],tblQuestions[Subtopic]))
